 * Running on http://0.0.0.0:36666/ (Press CTRL+C to quit)
 * Restarting with stat
 * Debugger is active!
 * Debugger PIN: 243-733-152
 * Running on http://0.0.0.0:36666/ (Press CTRL+C to quit)
 * Restarting with stat
 * Debugger is active!
 * Debugger PIN: 243-733-152
113.140.11.124 - - [08/Apr/2017 22:02:50] "GET /todo/api/v1.0/get_user_info/test HTTP/1.1" 200 -
113.140.11.124 - - [08/Apr/2017 22:03:05] "GET /todo/api/v1.0/get_iot_monitor/ HTTP/1.1" 200 -
113.140.11.124 - - [08/Apr/2017 22:07:58] "GET /todo/api/v1.0/get_user_info/s HTTP/1.1" 200 -
113.140.11.124 - - [08/Apr/2017 22:09:30] "GET /todo/api/v1.0/get_user_info/s HTTP/1.1" 200 -
113.140.11.124 - - [08/Apr/2017 22:10:15] "GET /todo/api/v1.0/get_user_info/s HTTP/1.1" 200 -
 * Running on http://0.0.0.0:36666/ (Press CTRL+C to quit)
 * Restarting with stat
 * Debugger is active!
 * Debugger PIN: 243-733-152
113.140.11.124 - - [08/Apr/2017 22:20:16] "GET /todo/api/v1.0/get_iot_monitor/ HTTP/1.1" 200 -
113.140.11.124 - - [08/Apr/2017 22:20:34] "GET /todo/api/v1.0/get_user_info/s HTTP/1.1" 200 -
113.140.11.124 - - [08/Apr/2017 22:20:49] "GET /todo/api/v1.0/get_user_info/s HTTP/1.1" 200 -
113.140.11.124 - - [08/Apr/2017 22:20:50] "GET /todo/api/v1.0/get_user_info/s HTTP/1.1" 200 -
113.140.11.124 - - [08/Apr/2017 22:21:15] "GET /todo/api/v1.0/get_user_info/s HTTP/1.1" 200 -
113.140.11.124 - - [08/Apr/2017 22:23:14] "GET /todo/api/v1.0/get_user_info/s HTTP/1.1" 200 -
113.140.11.122 - - [08/Apr/2017 22:23:16] "GET /todo/api/v1.0/get_user_info/test HTTP/1.1" 200 -
113.140.11.122 - - [08/Apr/2017 22:23:16] "GET /favicon.ico HTTP/1.1" 404 -
113.140.11.122 - - [08/Apr/2017 22:23:20] "GET /todo/api/v1.0/get_iot_equip/ HTTP/1.1" 200 -
113.140.11.122 - - [08/Apr/2017 22:23:20] "GET /favicon.ico HTTP/1.1" 404 -
113.140.11.122 - - [08/Apr/2017 22:23:35] "GET /todo/api/v1.0/update_iot_monitor/ HTTP/1.1" 405 -
Traceback (most recent call last):
  File "/usr/lib/python2.7/SocketServer.py", line 596, in process_request_thread
    self.finish_request(request, client_address)
  File "/usr/lib/python2.7/SocketServer.py", line 331, in finish_request
    self.RequestHandlerClass(request, client_address, self)
  File "/usr/lib/python2.7/SocketServer.py", line 652, in __init__
    self.handle()
  File "/usr/local/lib/python2.7/dist-packages/werkzeug/serving.py", line 232, in handle
    rv = BaseHTTPRequestHandler.handle(self)
  File "/usr/lib/python2.7/BaseHTTPServer.py", line 340, in handle
    self.handle_one_request()
  File "/usr/local/lib/python2.7/dist-packages/werkzeug/serving.py", line 263, in handle_one_request
    self.raw_requestline = self.rfile.readline()
IOError: [Errno 104] Connection reset by peer
113.140.11.122 - - [08/Apr/2017 22:24:48] "GET /todo/api/v1.0/get_iot_equip/ HTTP/1.1" 200 -
113.140.11.124 - - [08/Apr/2017 22:35:00] "GET /todo/api/v1.0/get_user_info/s HTTP/1.1" 200 -
113.140.11.124 - - [08/Apr/2017 23:09:11] "GET /todo/api/v1.0/get_user_info/test HTTP/1.1" 200 -
221.11.61.208 - - [08/Apr/2017 23:11:12] "GET /todo/api/v1.0/get_user_info/test HTTP/1.1" 200 -
221.11.61.208 - - [08/Apr/2017 23:11:12] "GET /favicon.ico HTTP/1.1" 404 -
113.140.11.124 - - [08/Apr/2017 23:17:24] "GET /todo/api/v1.0/get_user_info/test HTTP/1.1" 200 -
113.140.11.124 - - [08/Apr/2017 23:17:29] "GET /todo/api/v1.0/get_user_info/test HTTP/1.1" 200 -
113.140.11.124 - - [08/Apr/2017 23:17:41] "GET /todo/api/v1.0/get_user_monitor/test HTTP/1.1" 200 -
113.140.11.124 - - [08/Apr/2017 23:17:45] "GET /todo/api/v1.0/update_user_monitor/ HTTP/1.1" 405 -
101.226.33.227 - - [08/Apr/2017 23:17:55] "GET /todo/api/v1.0/update_user_monitor HTTP/1.1" 405 -
113.140.11.124 - - [08/Apr/2017 23:18:21] "GET /todo/api/v1.0/get_iot_equip/ HTTP/1.1" 200 -
113.140.11.124 - - [08/Apr/2017 23:18:22] "GET /favicon.ico HTTP/1.1" 404 -
113.140.11.124 - - [08/Apr/2017 23:18:22] "GET /favicon.ico HTTP/1.1" 404 -
113.140.11.122 - - [08/Apr/2017 23:35:21] "GET /todo/api/v1.0/get_user_info/test HTTP/1.1" 200 -
120.25.245.145 - - [09/Apr/2017 00:05:42] "GET /todo/api/v1.0/get_user_info/test HTTP/1.1" 200 -
123.138.79.7 - - [09/Apr/2017 00:44:49] "GET /todo/api/v1.0/get_user_info/test HTTP/1.1" 200 -
123.138.79.7 - - [09/Apr/2017 00:45:06] "GET /favicon.ico HTTP/1.1" 404 -
123.138.79.7 - - [09/Apr/2017 00:45:20] "GET /todo/api/v1.0/get_user_monitor/test HTTP/1.1" 200 -
123.138.79.7 - - [09/Apr/2017 00:45:20] "GET /todo/api/v1.0/get_user_monitor/test HTTP/1.1" 200 -
123.138.79.7 - - [09/Apr/2017 01:10:07] "GET /todo/api/v1.0/get_user_info/test HTTP/1.1" 200 -
123.138.79.7 - - [09/Apr/2017 01:18:47] "GET /todo/api/v1.0/get_user_info/test HTTP/1.1" 200 -
123.138.79.7 - - [09/Apr/2017 01:18:47] "GET /todo/api/v1.0/get_user_monitor/test HTTP/1.1" 200 -
/usr/local/lib/python2.7/dist-packages/werkzeug/filesystem.py:63: BrokenFilesystemWarning: Detected a misconfigured UNIX filesystem: Will use UTF-8 as filesystem encoding instead of 'ANSI_X3.4-1968'
  BrokenFilesystemWarning)
123.138.79.7 - - [09/Apr/2017 01:21:55] "POST /todo/api/v1.0/update_user_info/ HTTP/1.1" 500 -
Traceback (most recent call last):
  File "/usr/local/lib/python2.7/dist-packages/flask/app.py", line 1997, in __call__
    return self.wsgi_app(environ, start_response)
  File "/usr/local/lib/python2.7/dist-packages/flask/app.py", line 1985, in wsgi_app
    response = self.handle_exception(e)
  File "/usr/local/lib/python2.7/dist-packages/flask/app.py", line 1540, in handle_exception
    reraise(exc_type, exc_value, tb)
  File "/usr/local/lib/python2.7/dist-packages/flask/app.py", line 1982, in wsgi_app
    response = self.full_dispatch_request()
  File "/usr/local/lib/python2.7/dist-packages/flask/app.py", line 1614, in full_dispatch_request
    rv = self.handle_user_exception(e)
  File "/usr/local/lib/python2.7/dist-packages/flask/app.py", line 1517, in handle_user_exception
    reraise(exc_type, exc_value, tb)
  File "/usr/local/lib/python2.7/dist-packages/flask/app.py", line 1612, in full_dispatch_request
    rv = self.dispatch_request()
  File "/usr/local/lib/python2.7/dist-packages/flask/app.py", line 1598, in dispatch_request
    return self.view_functions[rule.endpoint](**req.view_args)
  File "/root/webAPI/app.py", line 88, in update_user_info
    updatedb.update_user_info(host,user_name,user_age,user_weight,user_height,user_blood_sugar,user_blood_pressure)
  File "/root/webAPI/updatedb.py", line 31, in update_user_info
    send_to_db(host,port,db,sql)
  File "/root/webAPI/updatedb.py", line 8, in send_to_db
    conn = pymysql.connect(host=host,user='root',passwd='112.74.171.161',port=port,db=db)
  File "/usr/lib/python2.7/dist-packages/pymysql/__init__.py", line 88, in Connect
    return Connection(*args, **kwargs)
  File "/usr/lib/python2.7/dist-packages/pymysql/connections.py", line 679, in __init__
    self.connect()
  File "/usr/lib/python2.7/dist-packages/pymysql/connections.py", line 891, in connect
    self._request_authentication()
  File "/usr/lib/python2.7/dist-packages/pymysql/connections.py", line 1097, in _request_authentication
    auth_packet = self._read_packet()
  File "/usr/lib/python2.7/dist-packages/pymysql/connections.py", line 966, in _read_packet
    packet.check_error()
  File "/usr/lib/python2.7/dist-packages/pymysql/connections.py", line 394, in check_error
    err.raise_mysql_exception(self._data)
  File "/usr/lib/python2.7/dist-packages/pymysql/err.py", line 120, in raise_mysql_exception
    _check_mysql_exception(errinfo)
  File "/usr/lib/python2.7/dist-packages/pymysql/err.py", line 112, in _check_mysql_exception
    raise errorclass(errno, errorvalue)
OperationalError: (1045, u"Access denied for user 'root'@'112.74.171.161' (using password: YES)")
123.138.79.7 - - [09/Apr/2017 01:22:51] "GET /todo/api/v1.0/get_user_info/test HTTP/1.1" 200 -
123.138.79.7 - - [09/Apr/2017 01:22:51] "GET /todo/api/v1.0/get_user_monitor/test HTTP/1.1" 200 -
123.138.79.7 - - [09/Apr/2017 01:26:02] "POST /todo/api/v1.0/update_user_info/ HTTP/1.1" 500 -
Traceback (most recent call last):
  File "/usr/local/lib/python2.7/dist-packages/flask/app.py", line 1997, in __call__
    return self.wsgi_app(environ, start_response)
  File "/usr/local/lib/python2.7/dist-packages/flask/app.py", line 1985, in wsgi_app
    response = self.handle_exception(e)
  File "/usr/local/lib/python2.7/dist-packages/flask/app.py", line 1540, in handle_exception
    reraise(exc_type, exc_value, tb)
  File "/usr/local/lib/python2.7/dist-packages/flask/app.py", line 1982, in wsgi_app
    response = self.full_dispatch_request()
  File "/usr/local/lib/python2.7/dist-packages/flask/app.py", line 1614, in full_dispatch_request
    rv = self.handle_user_exception(e)
  File "/usr/local/lib/python2.7/dist-packages/flask/app.py", line 1517, in handle_user_exception
    reraise(exc_type, exc_value, tb)
  File "/usr/local/lib/python2.7/dist-packages/flask/app.py", line 1612, in full_dispatch_request
    rv = self.dispatch_request()
  File "/usr/local/lib/python2.7/dist-packages/flask/app.py", line 1598, in dispatch_request
    return self.view_functions[rule.endpoint](**req.view_args)
  File "/root/webAPI/app.py", line 88, in update_user_info
    updatedb.update_user_info(host,user_name,user_age,user_weight,user_height,user_blood_sugar,user_blood_pressure)
  File "/root/webAPI/updatedb.py", line 31, in update_user_info
    send_to_db(host,port,db,sql)
  File "/root/webAPI/updatedb.py", line 8, in send_to_db
    conn = pymysql.connect(host=host,user='root',passwd='112.74.171.161',port=port,db=db)
  File "/usr/lib/python2.7/dist-packages/pymysql/__init__.py", line 88, in Connect
    return Connection(*args, **kwargs)
  File "/usr/lib/python2.7/dist-packages/pymysql/connections.py", line 679, in __init__
    self.connect()
  File "/usr/lib/python2.7/dist-packages/pymysql/connections.py", line 891, in connect
    self._request_authentication()
  File "/usr/lib/python2.7/dist-packages/pymysql/connections.py", line 1097, in _request_authentication
    auth_packet = self._read_packet()
  File "/usr/lib/python2.7/dist-packages/pymysql/connections.py", line 966, in _read_packet
    packet.check_error()
  File "/usr/lib/python2.7/dist-packages/pymysql/connections.py", line 394, in check_error
    err.raise_mysql_exception(self._data)
  File "/usr/lib/python2.7/dist-packages/pymysql/err.py", line 120, in raise_mysql_exception
    _check_mysql_exception(errinfo)
  File "/usr/lib/python2.7/dist-packages/pymysql/err.py", line 112, in _check_mysql_exception
    raise errorclass(errno, errorvalue)
OperationalError: (1045, u"Access denied for user 'root'@'112.74.171.161' (using password: YES)")
